[2022-03-30 20:48:46,415 views ERROR] 
Traceback (most recent call last):
  File "D:\Python\Django\Blog\venv\lib\site-packages\django\core\handlers\exception.py", line 47, in inner
    response = get_response(request)
  File "D:\Python\Django\Blog\venv\lib\site-packages\django\core\handlers\base.py", line 181, in _get_response
    response = wrapped_callback(request, *callback_args, **callback_kwargs)
  File "D:\Python\Django\Blog\venv\lib\site-packages\django\views\generic\base.py", line 69, in view
    return self.dispatch(request, *args, **kwargs)
  File "D:\Python\Django\Blog\venv\lib\site-packages\django\views\generic\base.py", line 101, in dispatch
    return handler(request, *args, **kwargs)
  File "D:\Python\Django\Blog\venv\lib\site-packages\django\views\generic\detail.py", line 106, in get
    self.object = self.get_object()
  File "D:\Python\Django\Blog\blog\views.py", line 25, in get_object
    raise Http404('Article is not exists')
django.http.response.Http404: Article is not exists

[2022-03-30 20:52:20,819 views ERROR] 
Traceback (most recent call last):
  File "D:\Python\Django\Blog\venv\lib\site-packages\django\core\handlers\exception.py", line 47, in inner
    response = get_response(request)
  File "D:\Python\Django\Blog\venv\lib\site-packages\django\core\handlers\base.py", line 181, in _get_response
    response = wrapped_callback(request, *callback_args, **callback_kwargs)
  File "D:\Python\Django\Blog\venv\lib\site-packages\django\views\generic\base.py", line 69, in view
    return self.dispatch(request, *args, **kwargs)
  File "D:\Python\Django\Blog\venv\lib\site-packages\django\views\generic\base.py", line 101, in dispatch
    return handler(request, *args, **kwargs)
  File "D:\Python\Django\Blog\venv\lib\site-packages\django\views\generic\detail.py", line 106, in get
    self.object = self.get_object()
  File "D:\Python\Django\Blog\blog\views.py", line 20, in get_object
    1/0
ZeroDivisionError: division by zero

[2022-03-30 20:53:24,999 views ERROR] 
Traceback (most recent call last):
  File "D:\Python\Django\Blog\venv\lib\site-packages\django\core\handlers\exception.py", line 47, in inner
    response = get_response(request)
  File "D:\Python\Django\Blog\venv\lib\site-packages\django\core\handlers\base.py", line 181, in _get_response
    response = wrapped_callback(request, *callback_args, **callback_kwargs)
  File "D:\Python\Django\Blog\venv\lib\site-packages\django\views\generic\base.py", line 69, in view
    return self.dispatch(request, *args, **kwargs)
  File "D:\Python\Django\Blog\venv\lib\site-packages\django\views\generic\base.py", line 101, in dispatch
    return handler(request, *args, **kwargs)
  File "D:\Python\Django\Blog\venv\lib\site-packages\django\views\generic\detail.py", line 106, in get
    self.object = self.get_object()
  File "D:\Python\Django\Blog\blog\views.py", line 20, in get_object
    1/0
ZeroDivisionError: division by zero

[2022-03-30 21:47:34,000 views ERROR] 
Traceback (most recent call last):
  File "D:\Python\Django\Blog\venv\lib\site-packages\django\core\handlers\exception.py", line 47, in inner
    response = get_response(request)
  File "D:\Python\Django\Blog\venv\lib\site-packages\django\core\handlers\base.py", line 167, in _get_response
    callback, callback_args, callback_kwargs = self.resolve_request(request)
  File "D:\Python\Django\Blog\venv\lib\site-packages\django\core\handlers\base.py", line 290, in resolve_request
    resolver_match = resolver.resolve(request.path_info)
  File "D:\Python\Django\Blog\venv\lib\site-packages\django\urls\resolvers.py", line 619, in resolve
    raise Resolver404({'tried': tried, 'path': new_path})
django.urls.exceptions.Resolver404: {'tried': [[<URLResolver <URLPattern list> (admin:admin) 'admin/'>], [<URLResolver <module 'user.urls' from 'D:\\Python\\Django\\Blog\\user\\urls.py'> (None:None) ''>, <URLPattern 'auth/register' [name='register']>], [<URLResolver <module 'user.urls' from 'D:\\Python\\Django\\Blog\\user\\urls.py'> (None:None) ''>, <URLPattern 'auth/login' [name='login']>], [<URLResolver <module 'user.urls' from 'D:\\Python\\Django\\Blog\\user\\urls.py'> (None:None) ''>, <URLPattern 'auth/logout' [name='logout']>], [<URLResolver <module 'blog.urls' from 'D:\\Python\\Django\\Blog\\blog\\urls.py'> (blog:blog) ''>, <URLPattern '' [name='index']>], [<URLResolver <module 'blog.urls' from 'D:\\Python\\Django\\Blog\\blog\\urls.py'> (blog:blog) ''>, <URLPattern 'search/result' [name='search']>], [<URLResolver <module 'blog.urls' from 'D:\\Python\\Django\\Blog\\blog\\urls.py'> (blog:blog) ''>, <URLPattern '<slug:category_slug>' [name='category']>], [<URLResolver <module 'blog.urls' from 'D:\\Python\\Django\\Blog\\blog\\urls.py'> (blog:blog) ''>, <URLPattern 'tags/<slug:tag_slug>' [name='tag']>], [<URLResolver <module 'blog.urls' from 'D:\\Python\\Django\\Blog\\blog\\urls.py'> (blog:blog) ''>, <URLPattern '<slug:category_slug>/<slug:post_slug>' [name='post']>]], 'path': 'favicon.ico'}

[2022-03-30 21:47:37,481 views ERROR] 
Traceback (most recent call last):
  File "D:\Python\Django\Blog\venv\lib\site-packages\django\core\handlers\exception.py", line 47, in inner
    response = get_response(request)
  File "D:\Python\Django\Blog\venv\lib\site-packages\django\core\handlers\base.py", line 181, in _get_response
    response = wrapped_callback(request, *callback_args, **callback_kwargs)
  File "D:\Python\Django\Blog\venv\lib\site-packages\django\views\generic\base.py", line 69, in view
    return self.dispatch(request, *args, **kwargs)
  File "D:\Python\Django\Blog\venv\lib\site-packages\django\views\generic\base.py", line 101, in dispatch
    return handler(request, *args, **kwargs)
  File "D:\Python\Django\Blog\venv\lib\site-packages\django\views\generic\detail.py", line 106, in get
    self.object = self.get_object()
  File "D:\Python\Django\Blog\blog\views.py", line 20, in get_object
    1/0
ZeroDivisionError: division by zero

[2022-03-30 21:53:19,817 views ERROR] 
Traceback (most recent call last):
  File "D:\Python\Django\Blog\venv\lib\site-packages\django\core\handlers\exception.py", line 47, in inner
    response = get_response(request)
  File "D:\Python\Django\Blog\venv\lib\site-packages\django\core\handlers\base.py", line 181, in _get_response
    response = wrapped_callback(request, *callback_args, **callback_kwargs)
  File "D:\Python\Django\Blog\venv\lib\site-packages\django\views\generic\base.py", line 69, in view
    return self.dispatch(request, *args, **kwargs)
  File "D:\Python\Django\Blog\venv\lib\site-packages\django\views\generic\base.py", line 101, in dispatch
    return handler(request, *args, **kwargs)
  File "D:\Python\Django\Blog\venv\lib\site-packages\django\views\generic\detail.py", line 106, in get
    self.object = self.get_object()
  File "D:\Python\Django\Blog\blog\views.py", line 24, in get_object
    raise Http404('Article is not exists')
django.http.response.Http404: Article is not exists

[2022-03-30 21:53:59,012 views ERROR] 
Traceback (most recent call last):
  File "D:\Python\Django\Blog\venv\lib\site-packages\django\core\handlers\exception.py", line 47, in inner
    response = get_response(request)
  File "D:\Python\Django\Blog\venv\lib\site-packages\django\core\handlers\base.py", line 167, in _get_response
    callback, callback_args, callback_kwargs = self.resolve_request(request)
  File "D:\Python\Django\Blog\venv\lib\site-packages\django\core\handlers\base.py", line 290, in resolve_request
    resolver_match = resolver.resolve(request.path_info)
  File "D:\Python\Django\Blog\venv\lib\site-packages\django\urls\resolvers.py", line 619, in resolve
    raise Resolver404({'tried': tried, 'path': new_path})
django.urls.exceptions.Resolver404: {'tried': [[<URLResolver <URLPattern list> (admin:admin) 'admin/'>], [<URLResolver <module 'user.urls' from 'D:\\Python\\Django\\Blog\\user\\urls.py'> (None:None) ''>, <URLPattern 'auth/register' [name='register']>], [<URLResolver <module 'user.urls' from 'D:\\Python\\Django\\Blog\\user\\urls.py'> (None:None) ''>, <URLPattern 'auth/login' [name='login']>], [<URLResolver <module 'user.urls' from 'D:\\Python\\Django\\Blog\\user\\urls.py'> (None:None) ''>, <URLPattern 'auth/logout' [name='logout']>], [<URLResolver <module 'blog.urls' from 'D:\\Python\\Django\\Blog\\blog\\urls.py'> (blog:blog) ''>, <URLPattern '' [name='index']>], [<URLResolver <module 'blog.urls' from 'D:\\Python\\Django\\Blog\\blog\\urls.py'> (blog:blog) ''>, <URLPattern 'search/result' [name='search']>], [<URLResolver <module 'blog.urls' from 'D:\\Python\\Django\\Blog\\blog\\urls.py'> (blog:blog) ''>, <URLPattern '<slug:category_slug>' [name='category']>], [<URLResolver <module 'blog.urls' from 'D:\\Python\\Django\\Blog\\blog\\urls.py'> (blog:blog) ''>, <URLPattern 'tags/<slug:tag_slug>' [name='tag']>], [<URLResolver <module 'blog.urls' from 'D:\\Python\\Django\\Blog\\blog\\urls.py'> (blog:blog) ''>, <URLPattern '<slug:category_slug>/<slug:post_slug>' [name='post']>]], 'path': 'static/blog/css/styles-detailview.css'}

[2022-03-30 21:54:03,158 views ERROR] 
Traceback (most recent call last):
  File "D:\Python\Django\Blog\venv\lib\site-packages\django\core\handlers\exception.py", line 47, in inner
    response = get_response(request)
  File "D:\Python\Django\Blog\venv\lib\site-packages\django\core\handlers\base.py", line 167, in _get_response
    callback, callback_args, callback_kwargs = self.resolve_request(request)
  File "D:\Python\Django\Blog\venv\lib\site-packages\django\core\handlers\base.py", line 290, in resolve_request
    resolver_match = resolver.resolve(request.path_info)
  File "D:\Python\Django\Blog\venv\lib\site-packages\django\urls\resolvers.py", line 619, in resolve
    raise Resolver404({'tried': tried, 'path': new_path})
django.urls.exceptions.Resolver404: {'tried': [[<URLResolver <URLPattern list> (admin:admin) 'admin/'>], [<URLResolver <module 'user.urls' from 'D:\\Python\\Django\\Blog\\user\\urls.py'> (None:None) ''>, <URLPattern 'auth/register' [name='register']>], [<URLResolver <module 'user.urls' from 'D:\\Python\\Django\\Blog\\user\\urls.py'> (None:None) ''>, <URLPattern 'auth/login' [name='login']>], [<URLResolver <module 'user.urls' from 'D:\\Python\\Django\\Blog\\user\\urls.py'> (None:None) ''>, <URLPattern 'auth/logout' [name='logout']>], [<URLResolver <module 'blog.urls' from 'D:\\Python\\Django\\Blog\\blog\\urls.py'> (blog:blog) ''>, <URLPattern '' [name='index']>], [<URLResolver <module 'blog.urls' from 'D:\\Python\\Django\\Blog\\blog\\urls.py'> (blog:blog) ''>, <URLPattern 'search/result' [name='search']>], [<URLResolver <module 'blog.urls' from 'D:\\Python\\Django\\Blog\\blog\\urls.py'> (blog:blog) ''>, <URLPattern '<slug:category_slug>' [name='category']>], [<URLResolver <module 'blog.urls' from 'D:\\Python\\Django\\Blog\\blog\\urls.py'> (blog:blog) ''>, <URLPattern 'tags/<slug:tag_slug>' [name='tag']>], [<URLResolver <module 'blog.urls' from 'D:\\Python\\Django\\Blog\\blog\\urls.py'> (blog:blog) ''>, <URLPattern '<slug:category_slug>/<slug:post_slug>' [name='post']>]], 'path': 'static/blog/css/styles-detailview.css'}

[2022-03-30 21:54:20,848 views ERROR] 
Traceback (most recent call last):
  File "D:\Python\Django\Blog\venv\lib\site-packages\django\core\handlers\exception.py", line 47, in inner
    response = get_response(request)
  File "D:\Python\Django\Blog\venv\lib\site-packages\django\core\handlers\base.py", line 167, in _get_response
    callback, callback_args, callback_kwargs = self.resolve_request(request)
  File "D:\Python\Django\Blog\venv\lib\site-packages\django\core\handlers\base.py", line 290, in resolve_request
    resolver_match = resolver.resolve(request.path_info)
  File "D:\Python\Django\Blog\venv\lib\site-packages\django\urls\resolvers.py", line 619, in resolve
    raise Resolver404({'tried': tried, 'path': new_path})
django.urls.exceptions.Resolver404: {'tried': [[<URLResolver <URLPattern list> (admin:admin) 'admin/'>], [<URLResolver <module 'user.urls' from 'D:\\Python\\Django\\Blog\\user\\urls.py'> (None:None) ''>, <URLPattern 'auth/register' [name='register']>], [<URLResolver <module 'user.urls' from 'D:\\Python\\Django\\Blog\\user\\urls.py'> (None:None) ''>, <URLPattern 'auth/login' [name='login']>], [<URLResolver <module 'user.urls' from 'D:\\Python\\Django\\Blog\\user\\urls.py'> (None:None) ''>, <URLPattern 'auth/logout' [name='logout']>], [<URLResolver <module 'blog.urls' from 'D:\\Python\\Django\\Blog\\blog\\urls.py'> (blog:blog) ''>, <URLPattern '' [name='index']>], [<URLResolver <module 'blog.urls' from 'D:\\Python\\Django\\Blog\\blog\\urls.py'> (blog:blog) ''>, <URLPattern 'search/result' [name='search']>], [<URLResolver <module 'blog.urls' from 'D:\\Python\\Django\\Blog\\blog\\urls.py'> (blog:blog) ''>, <URLPattern '<slug:category_slug>' [name='category']>], [<URLResolver <module 'blog.urls' from 'D:\\Python\\Django\\Blog\\blog\\urls.py'> (blog:blog) ''>, <URLPattern 'tags/<slug:tag_slug>' [name='tag']>], [<URLResolver <module 'blog.urls' from 'D:\\Python\\Django\\Blog\\blog\\urls.py'> (blog:blog) ''>, <URLPattern '<slug:category_slug>/<slug:post_slug>' [name='post']>]], 'path': 'static/blog/css/styles-detailview.css'}

[2022-03-30 21:55:21,433 views ERROR] 
Traceback (most recent call last):
  File "D:\Python\Django\Blog\venv\lib\site-packages\django\core\handlers\exception.py", line 47, in inner
    response = get_response(request)
  File "D:\Python\Django\Blog\venv\lib\site-packages\django\core\handlers\base.py", line 167, in _get_response
    callback, callback_args, callback_kwargs = self.resolve_request(request)
  File "D:\Python\Django\Blog\venv\lib\site-packages\django\core\handlers\base.py", line 290, in resolve_request
    resolver_match = resolver.resolve(request.path_info)
  File "D:\Python\Django\Blog\venv\lib\site-packages\django\urls\resolvers.py", line 619, in resolve
    raise Resolver404({'tried': tried, 'path': new_path})
django.urls.exceptions.Resolver404: {'tried': [[<URLResolver <URLPattern list> (admin:admin) 'admin/'>], [<URLResolver <module 'user.urls' from 'D:\\Python\\Django\\Blog\\user\\urls.py'> (None:None) ''>, <URLPattern 'auth/register' [name='register']>], [<URLResolver <module 'user.urls' from 'D:\\Python\\Django\\Blog\\user\\urls.py'> (None:None) ''>, <URLPattern 'auth/login' [name='login']>], [<URLResolver <module 'user.urls' from 'D:\\Python\\Django\\Blog\\user\\urls.py'> (None:None) ''>, <URLPattern 'auth/logout' [name='logout']>], [<URLResolver <module 'blog.urls' from 'D:\\Python\\Django\\Blog\\blog\\urls.py'> (blog:blog) ''>, <URLPattern '' [name='index']>], [<URLResolver <module 'blog.urls' from 'D:\\Python\\Django\\Blog\\blog\\urls.py'> (blog:blog) ''>, <URLPattern 'search/result' [name='search']>], [<URLResolver <module 'blog.urls' from 'D:\\Python\\Django\\Blog\\blog\\urls.py'> (blog:blog) ''>, <URLPattern '<slug:category_slug>' [name='category']>], [<URLResolver <module 'blog.urls' from 'D:\\Python\\Django\\Blog\\blog\\urls.py'> (blog:blog) ''>, <URLPattern 'tags/<slug:tag_slug>' [name='tag']>], [<URLResolver <module 'blog.urls' from 'D:\\Python\\Django\\Blog\\blog\\urls.py'> (blog:blog) ''>, <URLPattern '<slug:category_slug>/<slug:post_slug>' [name='post']>]], 'path': 'static/blog/css/styles-detailview.css'}

[2022-03-30 21:55:52,811 views ERROR] 
Traceback (most recent call last):
  File "D:\Python\Django\Blog\venv\lib\site-packages\django\core\handlers\exception.py", line 47, in inner
    response = get_response(request)
  File "D:\Python\Django\Blog\venv\lib\site-packages\django\core\handlers\base.py", line 167, in _get_response
    callback, callback_args, callback_kwargs = self.resolve_request(request)
  File "D:\Python\Django\Blog\venv\lib\site-packages\django\core\handlers\base.py", line 290, in resolve_request
    resolver_match = resolver.resolve(request.path_info)
  File "D:\Python\Django\Blog\venv\lib\site-packages\django\urls\resolvers.py", line 619, in resolve
    raise Resolver404({'tried': tried, 'path': new_path})
django.urls.exceptions.Resolver404: {'tried': [[<URLResolver <URLPattern list> (admin:admin) 'admin/'>], [<URLResolver <module 'user.urls' from 'D:\\Python\\Django\\Blog\\user\\urls.py'> (None:None) ''>, <URLPattern 'auth/register' [name='register']>], [<URLResolver <module 'user.urls' from 'D:\\Python\\Django\\Blog\\user\\urls.py'> (None:None) ''>, <URLPattern 'auth/login' [name='login']>], [<URLResolver <module 'user.urls' from 'D:\\Python\\Django\\Blog\\user\\urls.py'> (None:None) ''>, <URLPattern 'auth/logout' [name='logout']>], [<URLResolver <module 'blog.urls' from 'D:\\Python\\Django\\Blog\\blog\\urls.py'> (blog:blog) ''>, <URLPattern '' [name='index']>], [<URLResolver <module 'blog.urls' from 'D:\\Python\\Django\\Blog\\blog\\urls.py'> (blog:blog) ''>, <URLPattern 'search/result' [name='search']>], [<URLResolver <module 'blog.urls' from 'D:\\Python\\Django\\Blog\\blog\\urls.py'> (blog:blog) ''>, <URLPattern '<slug:category_slug>' [name='category']>], [<URLResolver <module 'blog.urls' from 'D:\\Python\\Django\\Blog\\blog\\urls.py'> (blog:blog) ''>, <URLPattern 'tags/<slug:tag_slug>' [name='tag']>], [<URLResolver <module 'blog.urls' from 'D:\\Python\\Django\\Blog\\blog\\urls.py'> (blog:blog) ''>, <URLPattern '<slug:category_slug>/<slug:post_slug>' [name='post']>]], 'path': 'static/blog/css/styles-detailview.css'}

[2022-03-30 21:55:59,580 views ERROR] 
Traceback (most recent call last):
  File "D:\Python\Django\Blog\venv\lib\site-packages\django\core\handlers\exception.py", line 47, in inner
    response = get_response(request)
  File "D:\Python\Django\Blog\venv\lib\site-packages\django\core\handlers\base.py", line 167, in _get_response
    callback, callback_args, callback_kwargs = self.resolve_request(request)
  File "D:\Python\Django\Blog\venv\lib\site-packages\django\core\handlers\base.py", line 290, in resolve_request
    resolver_match = resolver.resolve(request.path_info)
  File "D:\Python\Django\Blog\venv\lib\site-packages\django\urls\resolvers.py", line 619, in resolve
    raise Resolver404({'tried': tried, 'path': new_path})
django.urls.exceptions.Resolver404: {'tried': [[<URLResolver <URLPattern list> (admin:admin) 'admin/'>], [<URLResolver <module 'user.urls' from 'D:\\Python\\Django\\Blog\\user\\urls.py'> (None:None) ''>, <URLPattern 'auth/register' [name='register']>], [<URLResolver <module 'user.urls' from 'D:\\Python\\Django\\Blog\\user\\urls.py'> (None:None) ''>, <URLPattern 'auth/login' [name='login']>], [<URLResolver <module 'user.urls' from 'D:\\Python\\Django\\Blog\\user\\urls.py'> (None:None) ''>, <URLPattern 'auth/logout' [name='logout']>], [<URLResolver <module 'blog.urls' from 'D:\\Python\\Django\\Blog\\blog\\urls.py'> (blog:blog) ''>, <URLPattern '' [name='index']>], [<URLResolver <module 'blog.urls' from 'D:\\Python\\Django\\Blog\\blog\\urls.py'> (blog:blog) ''>, <URLPattern 'search/result' [name='search']>], [<URLResolver <module 'blog.urls' from 'D:\\Python\\Django\\Blog\\blog\\urls.py'> (blog:blog) ''>, <URLPattern '<slug:category_slug>' [name='category']>], [<URLResolver <module 'blog.urls' from 'D:\\Python\\Django\\Blog\\blog\\urls.py'> (blog:blog) ''>, <URLPattern 'tags/<slug:tag_slug>' [name='tag']>], [<URLResolver <module 'blog.urls' from 'D:\\Python\\Django\\Blog\\blog\\urls.py'> (blog:blog) ''>, <URLPattern '<slug:category_slug>/<slug:post_slug>' [name='post']>]], 'path': 'static/blog/css/styles-detailview.css'}

[2022-03-30 21:56:00,053 views ERROR] 
Traceback (most recent call last):
  File "D:\Python\Django\Blog\venv\lib\site-packages\django\core\handlers\exception.py", line 47, in inner
    response = get_response(request)
  File "D:\Python\Django\Blog\venv\lib\site-packages\django\core\handlers\base.py", line 167, in _get_response
    callback, callback_args, callback_kwargs = self.resolve_request(request)
  File "D:\Python\Django\Blog\venv\lib\site-packages\django\core\handlers\base.py", line 290, in resolve_request
    resolver_match = resolver.resolve(request.path_info)
  File "D:\Python\Django\Blog\venv\lib\site-packages\django\urls\resolvers.py", line 619, in resolve
    raise Resolver404({'tried': tried, 'path': new_path})
django.urls.exceptions.Resolver404: {'tried': [[<URLResolver <URLPattern list> (admin:admin) 'admin/'>], [<URLResolver <module 'user.urls' from 'D:\\Python\\Django\\Blog\\user\\urls.py'> (None:None) ''>, <URLPattern 'auth/register' [name='register']>], [<URLResolver <module 'user.urls' from 'D:\\Python\\Django\\Blog\\user\\urls.py'> (None:None) ''>, <URLPattern 'auth/login' [name='login']>], [<URLResolver <module 'user.urls' from 'D:\\Python\\Django\\Blog\\user\\urls.py'> (None:None) ''>, <URLPattern 'auth/logout' [name='logout']>], [<URLResolver <module 'blog.urls' from 'D:\\Python\\Django\\Blog\\blog\\urls.py'> (blog:blog) ''>, <URLPattern '' [name='index']>], [<URLResolver <module 'blog.urls' from 'D:\\Python\\Django\\Blog\\blog\\urls.py'> (blog:blog) ''>, <URLPattern 'search/result' [name='search']>], [<URLResolver <module 'blog.urls' from 'D:\\Python\\Django\\Blog\\blog\\urls.py'> (blog:blog) ''>, <URLPattern '<slug:category_slug>' [name='category']>], [<URLResolver <module 'blog.urls' from 'D:\\Python\\Django\\Blog\\blog\\urls.py'> (blog:blog) ''>, <URLPattern 'tags/<slug:tag_slug>' [name='tag']>], [<URLResolver <module 'blog.urls' from 'D:\\Python\\Django\\Blog\\blog\\urls.py'> (blog:blog) ''>, <URLPattern '<slug:category_slug>/<slug:post_slug>' [name='post']>]], 'path': 'media/images/2022/03/26/original-1e3a9b0322e85ba64376e6de6a9a0065.jpg'}

[2022-03-30 21:56:00,281 views ERROR] 
Traceback (most recent call last):
  File "D:\Python\Django\Blog\venv\lib\site-packages\django\core\handlers\exception.py", line 47, in inner
    response = get_response(request)
  File "D:\Python\Django\Blog\venv\lib\site-packages\django\core\handlers\base.py", line 167, in _get_response
    callback, callback_args, callback_kwargs = self.resolve_request(request)
  File "D:\Python\Django\Blog\venv\lib\site-packages\django\core\handlers\base.py", line 290, in resolve_request
    resolver_match = resolver.resolve(request.path_info)
  File "D:\Python\Django\Blog\venv\lib\site-packages\django\urls\resolvers.py", line 619, in resolve
    raise Resolver404({'tried': tried, 'path': new_path})
django.urls.exceptions.Resolver404: {'tried': [[<URLResolver <URLPattern list> (admin:admin) 'admin/'>], [<URLResolver <module 'user.urls' from 'D:\\Python\\Django\\Blog\\user\\urls.py'> (None:None) ''>, <URLPattern 'auth/register' [name='register']>], [<URLResolver <module 'user.urls' from 'D:\\Python\\Django\\Blog\\user\\urls.py'> (None:None) ''>, <URLPattern 'auth/login' [name='login']>], [<URLResolver <module 'user.urls' from 'D:\\Python\\Django\\Blog\\user\\urls.py'> (None:None) ''>, <URLPattern 'auth/logout' [name='logout']>], [<URLResolver <module 'blog.urls' from 'D:\\Python\\Django\\Blog\\blog\\urls.py'> (blog:blog) ''>, <URLPattern '' [name='index']>], [<URLResolver <module 'blog.urls' from 'D:\\Python\\Django\\Blog\\blog\\urls.py'> (blog:blog) ''>, <URLPattern 'search/result' [name='search']>], [<URLResolver <module 'blog.urls' from 'D:\\Python\\Django\\Blog\\blog\\urls.py'> (blog:blog) ''>, <URLPattern '<slug:category_slug>' [name='category']>], [<URLResolver <module 'blog.urls' from 'D:\\Python\\Django\\Blog\\blog\\urls.py'> (blog:blog) ''>, <URLPattern 'tags/<slug:tag_slug>' [name='tag']>], [<URLResolver <module 'blog.urls' from 'D:\\Python\\Django\\Blog\\blog\\urls.py'> (blog:blog) ''>, <URLPattern '<slug:category_slug>/<slug:post_slug>' [name='post']>]], 'path': 'favicon.ico'}

[2022-03-30 21:56:04,424 views ERROR] 
Traceback (most recent call last):
  File "D:\Python\Django\Blog\venv\lib\site-packages\django\core\handlers\exception.py", line 47, in inner
    response = get_response(request)
  File "D:\Python\Django\Blog\venv\lib\site-packages\django\core\handlers\base.py", line 167, in _get_response
    callback, callback_args, callback_kwargs = self.resolve_request(request)
  File "D:\Python\Django\Blog\venv\lib\site-packages\django\core\handlers\base.py", line 290, in resolve_request
    resolver_match = resolver.resolve(request.path_info)
  File "D:\Python\Django\Blog\venv\lib\site-packages\django\urls\resolvers.py", line 619, in resolve
    raise Resolver404({'tried': tried, 'path': new_path})
django.urls.exceptions.Resolver404: {'tried': [[<URLResolver <URLPattern list> (admin:admin) 'admin/'>], [<URLResolver <module 'user.urls' from 'D:\\Python\\Django\\Blog\\user\\urls.py'> (None:None) ''>, <URLPattern 'auth/register' [name='register']>], [<URLResolver <module 'user.urls' from 'D:\\Python\\Django\\Blog\\user\\urls.py'> (None:None) ''>, <URLPattern 'auth/login' [name='login']>], [<URLResolver <module 'user.urls' from 'D:\\Python\\Django\\Blog\\user\\urls.py'> (None:None) ''>, <URLPattern 'auth/logout' [name='logout']>], [<URLResolver <module 'blog.urls' from 'D:\\Python\\Django\\Blog\\blog\\urls.py'> (blog:blog) ''>, <URLPattern '' [name='index']>], [<URLResolver <module 'blog.urls' from 'D:\\Python\\Django\\Blog\\blog\\urls.py'> (blog:blog) ''>, <URLPattern 'search/result' [name='search']>], [<URLResolver <module 'blog.urls' from 'D:\\Python\\Django\\Blog\\blog\\urls.py'> (blog:blog) ''>, <URLPattern '<slug:category_slug>' [name='category']>], [<URLResolver <module 'blog.urls' from 'D:\\Python\\Django\\Blog\\blog\\urls.py'> (blog:blog) ''>, <URLPattern 'tags/<slug:tag_slug>' [name='tag']>], [<URLResolver <module 'blog.urls' from 'D:\\Python\\Django\\Blog\\blog\\urls.py'> (blog:blog) ''>, <URLPattern '<slug:category_slug>/<slug:post_slug>' [name='post']>]], 'path': 'static/blog/css/styles-detailview.css'}

[2022-03-30 21:56:04,431 views ERROR] 
Traceback (most recent call last):
  File "D:\Python\Django\Blog\venv\lib\site-packages\django\core\handlers\exception.py", line 47, in inner
    response = get_response(request)
  File "D:\Python\Django\Blog\venv\lib\site-packages\django\core\handlers\base.py", line 167, in _get_response
    callback, callback_args, callback_kwargs = self.resolve_request(request)
  File "D:\Python\Django\Blog\venv\lib\site-packages\django\core\handlers\base.py", line 290, in resolve_request
    resolver_match = resolver.resolve(request.path_info)
  File "D:\Python\Django\Blog\venv\lib\site-packages\django\urls\resolvers.py", line 619, in resolve
    raise Resolver404({'tried': tried, 'path': new_path})
django.urls.exceptions.Resolver404: {'tried': [[<URLResolver <URLPattern list> (admin:admin) 'admin/'>], [<URLResolver <module 'user.urls' from 'D:\\Python\\Django\\Blog\\user\\urls.py'> (None:None) ''>, <URLPattern 'auth/register' [name='register']>], [<URLResolver <module 'user.urls' from 'D:\\Python\\Django\\Blog\\user\\urls.py'> (None:None) ''>, <URLPattern 'auth/login' [name='login']>], [<URLResolver <module 'user.urls' from 'D:\\Python\\Django\\Blog\\user\\urls.py'> (None:None) ''>, <URLPattern 'auth/logout' [name='logout']>], [<URLResolver <module 'blog.urls' from 'D:\\Python\\Django\\Blog\\blog\\urls.py'> (blog:blog) ''>, <URLPattern '' [name='index']>], [<URLResolver <module 'blog.urls' from 'D:\\Python\\Django\\Blog\\blog\\urls.py'> (blog:blog) ''>, <URLPattern 'search/result' [name='search']>], [<URLResolver <module 'blog.urls' from 'D:\\Python\\Django\\Blog\\blog\\urls.py'> (blog:blog) ''>, <URLPattern '<slug:category_slug>' [name='category']>], [<URLResolver <module 'blog.urls' from 'D:\\Python\\Django\\Blog\\blog\\urls.py'> (blog:blog) ''>, <URLPattern 'tags/<slug:tag_slug>' [name='tag']>], [<URLResolver <module 'blog.urls' from 'D:\\Python\\Django\\Blog\\blog\\urls.py'> (blog:blog) ''>, <URLPattern '<slug:category_slug>/<slug:post_slug>' [name='post']>]], 'path': 'media/images/2022/03/26/original-1e3a9b0322e85ba64376e6de6a9a0065.jpg'}

[2022-03-30 21:56:45,368 views ERROR] 
Traceback (most recent call last):
  File "D:\Python\Django\Blog\venv\lib\site-packages\django\core\handlers\exception.py", line 47, in inner
    response = get_response(request)
  File "D:\Python\Django\Blog\venv\lib\site-packages\django\core\handlers\base.py", line 167, in _get_response
    callback, callback_args, callback_kwargs = self.resolve_request(request)
  File "D:\Python\Django\Blog\venv\lib\site-packages\django\core\handlers\base.py", line 290, in resolve_request
    resolver_match = resolver.resolve(request.path_info)
  File "D:\Python\Django\Blog\venv\lib\site-packages\django\urls\resolvers.py", line 619, in resolve
    raise Resolver404({'tried': tried, 'path': new_path})
django.urls.exceptions.Resolver404: {'tried': [[<URLResolver <URLPattern list> (admin:admin) 'admin/'>], [<URLResolver <module 'user.urls' from 'D:\\Python\\Django\\Blog\\user\\urls.py'> (None:None) ''>, <URLPattern 'auth/register' [name='register']>], [<URLResolver <module 'user.urls' from 'D:\\Python\\Django\\Blog\\user\\urls.py'> (None:None) ''>, <URLPattern 'auth/login' [name='login']>], [<URLResolver <module 'user.urls' from 'D:\\Python\\Django\\Blog\\user\\urls.py'> (None:None) ''>, <URLPattern 'auth/logout' [name='logout']>], [<URLResolver <module 'blog.urls' from 'D:\\Python\\Django\\Blog\\blog\\urls.py'> (blog:blog) ''>, <URLPattern '' [name='index']>], [<URLResolver <module 'blog.urls' from 'D:\\Python\\Django\\Blog\\blog\\urls.py'> (blog:blog) ''>, <URLPattern 'search/result' [name='search']>], [<URLResolver <module 'blog.urls' from 'D:\\Python\\Django\\Blog\\blog\\urls.py'> (blog:blog) ''>, <URLPattern '<slug:category_slug>' [name='category']>], [<URLResolver <module 'blog.urls' from 'D:\\Python\\Django\\Blog\\blog\\urls.py'> (blog:blog) ''>, <URLPattern 'tags/<slug:tag_slug>' [name='tag']>], [<URLResolver <module 'blog.urls' from 'D:\\Python\\Django\\Blog\\blog\\urls.py'> (blog:blog) ''>, <URLPattern '<slug:category_slug>/<slug:post_slug>' [name='post']>]], 'path': 'media/images/2022/03/26/zinaida-bonami-v-moskovskom-dome-knigi_0fbd0cde24_opgh.jpg'}

[2022-03-30 21:56:45,371 views ERROR] 
Traceback (most recent call last):
  File "D:\Python\Django\Blog\venv\lib\site-packages\django\core\handlers\exception.py", line 47, in inner
    response = get_response(request)
  File "D:\Python\Django\Blog\venv\lib\site-packages\django\core\handlers\base.py", line 167, in _get_response
    callback, callback_args, callback_kwargs = self.resolve_request(request)
  File "D:\Python\Django\Blog\venv\lib\site-packages\django\core\handlers\base.py", line 290, in resolve_request
    resolver_match = resolver.resolve(request.path_info)
  File "D:\Python\Django\Blog\venv\lib\site-packages\django\urls\resolvers.py", line 619, in resolve
    raise Resolver404({'tried': tried, 'path': new_path})
django.urls.exceptions.Resolver404: {'tried': [[<URLResolver <URLPattern list> (admin:admin) 'admin/'>], [<URLResolver <module 'user.urls' from 'D:\\Python\\Django\\Blog\\user\\urls.py'> (None:None) ''>, <URLPattern 'auth/register' [name='register']>], [<URLResolver <module 'user.urls' from 'D:\\Python\\Django\\Blog\\user\\urls.py'> (None:None) ''>, <URLPattern 'auth/login' [name='login']>], [<URLResolver <module 'user.urls' from 'D:\\Python\\Django\\Blog\\user\\urls.py'> (None:None) ''>, <URLPattern 'auth/logout' [name='logout']>], [<URLResolver <module 'blog.urls' from 'D:\\Python\\Django\\Blog\\blog\\urls.py'> (blog:blog) ''>, <URLPattern '' [name='index']>], [<URLResolver <module 'blog.urls' from 'D:\\Python\\Django\\Blog\\blog\\urls.py'> (blog:blog) ''>, <URLPattern 'search/result' [name='search']>], [<URLResolver <module 'blog.urls' from 'D:\\Python\\Django\\Blog\\blog\\urls.py'> (blog:blog) ''>, <URLPattern '<slug:category_slug>' [name='category']>], [<URLResolver <module 'blog.urls' from 'D:\\Python\\Django\\Blog\\blog\\urls.py'> (blog:blog) ''>, <URLPattern 'tags/<slug:tag_slug>' [name='tag']>], [<URLResolver <module 'blog.urls' from 'D:\\Python\\Django\\Blog\\blog\\urls.py'> (blog:blog) ''>, <URLPattern '<slug:category_slug>/<slug:post_slug>' [name='post']>]], 'path': 'static/blog/css/styles-listview.css'}

[2022-03-30 21:56:45,427 views ERROR] 
Traceback (most recent call last):
  File "D:\Python\Django\Blog\venv\lib\site-packages\django\core\handlers\exception.py", line 47, in inner
    response = get_response(request)
  File "D:\Python\Django\Blog\venv\lib\site-packages\django\core\handlers\base.py", line 167, in _get_response
    callback, callback_args, callback_kwargs = self.resolve_request(request)
  File "D:\Python\Django\Blog\venv\lib\site-packages\django\core\handlers\base.py", line 290, in resolve_request
    resolver_match = resolver.resolve(request.path_info)
  File "D:\Python\Django\Blog\venv\lib\site-packages\django\urls\resolvers.py", line 619, in resolve
    raise Resolver404({'tried': tried, 'path': new_path})
django.urls.exceptions.Resolver404: {'tried': [[<URLResolver <URLPattern list> (admin:admin) 'admin/'>], [<URLResolver <module 'user.urls' from 'D:\\Python\\Django\\Blog\\user\\urls.py'> (None:None) ''>, <URLPattern 'auth/register' [name='register']>], [<URLResolver <module 'user.urls' from 'D:\\Python\\Django\\Blog\\user\\urls.py'> (None:None) ''>, <URLPattern 'auth/login' [name='login']>], [<URLResolver <module 'user.urls' from 'D:\\Python\\Django\\Blog\\user\\urls.py'> (None:None) ''>, <URLPattern 'auth/logout' [name='logout']>], [<URLResolver <module 'blog.urls' from 'D:\\Python\\Django\\Blog\\blog\\urls.py'> (blog:blog) ''>, <URLPattern '' [name='index']>], [<URLResolver <module 'blog.urls' from 'D:\\Python\\Django\\Blog\\blog\\urls.py'> (blog:blog) ''>, <URLPattern 'search/result' [name='search']>], [<URLResolver <module 'blog.urls' from 'D:\\Python\\Django\\Blog\\blog\\urls.py'> (blog:blog) ''>, <URLPattern '<slug:category_slug>' [name='category']>], [<URLResolver <module 'blog.urls' from 'D:\\Python\\Django\\Blog\\blog\\urls.py'> (blog:blog) ''>, <URLPattern 'tags/<slug:tag_slug>' [name='tag']>], [<URLResolver <module 'blog.urls' from 'D:\\Python\\Django\\Blog\\blog\\urls.py'> (blog:blog) ''>, <URLPattern '<slug:category_slug>/<slug:post_slug>' [name='post']>]], 'path': 'media/images/2022/03/26/original-1e3a9b0322e85ba64376e6de6a9a0065.jpg'}

[2022-03-30 21:57:06,811 views ERROR] 
Traceback (most recent call last):
  File "D:\Python\Django\Blog\venv\lib\site-packages\django\core\handlers\exception.py", line 47, in inner
    response = get_response(request)
  File "D:\Python\Django\Blog\venv\lib\site-packages\django\core\handlers\base.py", line 167, in _get_response
    callback, callback_args, callback_kwargs = self.resolve_request(request)
  File "D:\Python\Django\Blog\venv\lib\site-packages\django\core\handlers\base.py", line 290, in resolve_request
    resolver_match = resolver.resolve(request.path_info)
  File "D:\Python\Django\Blog\venv\lib\site-packages\django\urls\resolvers.py", line 619, in resolve
    raise Resolver404({'tried': tried, 'path': new_path})
django.urls.exceptions.Resolver404: {'tried': [[<URLResolver <URLPattern list> (admin:admin) 'admin/'>], [<URLResolver <module 'user.urls' from 'D:\\Python\\Django\\Blog\\user\\urls.py'> (None:None) ''>, <URLPattern 'auth/register' [name='register']>], [<URLResolver <module 'user.urls' from 'D:\\Python\\Django\\Blog\\user\\urls.py'> (None:None) ''>, <URLPattern 'auth/login' [name='login']>], [<URLResolver <module 'user.urls' from 'D:\\Python\\Django\\Blog\\user\\urls.py'> (None:None) ''>, <URLPattern 'auth/logout' [name='logout']>], [<URLResolver <module 'blog.urls' from 'D:\\Python\\Django\\Blog\\blog\\urls.py'> (blog:blog) ''>, <URLPattern '' [name='index']>], [<URLResolver <module 'blog.urls' from 'D:\\Python\\Django\\Blog\\blog\\urls.py'> (blog:blog) ''>, <URLPattern 'search/result' [name='search']>], [<URLResolver <module 'blog.urls' from 'D:\\Python\\Django\\Blog\\blog\\urls.py'> (blog:blog) ''>, <URLPattern '<slug:category_slug>' [name='category']>], [<URLResolver <module 'blog.urls' from 'D:\\Python\\Django\\Blog\\blog\\urls.py'> (blog:blog) ''>, <URLPattern 'tags/<slug:tag_slug>' [name='tag']>], [<URLResolver <module 'blog.urls' from 'D:\\Python\\Django\\Blog\\blog\\urls.py'> (blog:blog) ''>, <URLPattern '<slug:category_slug>/<slug:post_slug>' [name='post']>]], 'path': 'static/blog/css/styles-listview.css'}

[2022-03-30 21:57:06,813 views ERROR] 
Traceback (most recent call last):
  File "D:\Python\Django\Blog\venv\lib\site-packages\django\core\handlers\exception.py", line 47, in inner
    response = get_response(request)
  File "D:\Python\Django\Blog\venv\lib\site-packages\django\core\handlers\base.py", line 167, in _get_response
    callback, callback_args, callback_kwargs = self.resolve_request(request)
  File "D:\Python\Django\Blog\venv\lib\site-packages\django\core\handlers\base.py", line 290, in resolve_request
    resolver_match = resolver.resolve(request.path_info)
  File "D:\Python\Django\Blog\venv\lib\site-packages\django\urls\resolvers.py", line 619, in resolve
    raise Resolver404({'tried': tried, 'path': new_path})
django.urls.exceptions.Resolver404: {'tried': [[<URLResolver <URLPattern list> (admin:admin) 'admin/'>], [<URLResolver <module 'user.urls' from 'D:\\Python\\Django\\Blog\\user\\urls.py'> (None:None) ''>, <URLPattern 'auth/register' [name='register']>], [<URLResolver <module 'user.urls' from 'D:\\Python\\Django\\Blog\\user\\urls.py'> (None:None) ''>, <URLPattern 'auth/login' [name='login']>], [<URLResolver <module 'user.urls' from 'D:\\Python\\Django\\Blog\\user\\urls.py'> (None:None) ''>, <URLPattern 'auth/logout' [name='logout']>], [<URLResolver <module 'blog.urls' from 'D:\\Python\\Django\\Blog\\blog\\urls.py'> (blog:blog) ''>, <URLPattern '' [name='index']>], [<URLResolver <module 'blog.urls' from 'D:\\Python\\Django\\Blog\\blog\\urls.py'> (blog:blog) ''>, <URLPattern 'search/result' [name='search']>], [<URLResolver <module 'blog.urls' from 'D:\\Python\\Django\\Blog\\blog\\urls.py'> (blog:blog) ''>, <URLPattern '<slug:category_slug>' [name='category']>], [<URLResolver <module 'blog.urls' from 'D:\\Python\\Django\\Blog\\blog\\urls.py'> (blog:blog) ''>, <URLPattern 'tags/<slug:tag_slug>' [name='tag']>], [<URLResolver <module 'blog.urls' from 'D:\\Python\\Django\\Blog\\blog\\urls.py'> (blog:blog) ''>, <URLPattern '<slug:category_slug>/<slug:post_slug>' [name='post']>]], 'path': 'media/images/2022/03/26/original-1e3a9b0322e85ba64376e6de6a9a0065.jpg'}

[2022-03-30 21:57:06,851 views ERROR] 
Traceback (most recent call last):
  File "D:\Python\Django\Blog\venv\lib\site-packages\django\core\handlers\exception.py", line 47, in inner
    response = get_response(request)
  File "D:\Python\Django\Blog\venv\lib\site-packages\django\core\handlers\base.py", line 167, in _get_response
    callback, callback_args, callback_kwargs = self.resolve_request(request)
  File "D:\Python\Django\Blog\venv\lib\site-packages\django\core\handlers\base.py", line 290, in resolve_request
    resolver_match = resolver.resolve(request.path_info)
  File "D:\Python\Django\Blog\venv\lib\site-packages\django\urls\resolvers.py", line 619, in resolve
    raise Resolver404({'tried': tried, 'path': new_path})
django.urls.exceptions.Resolver404: {'tried': [[<URLResolver <URLPattern list> (admin:admin) 'admin/'>], [<URLResolver <module 'user.urls' from 'D:\\Python\\Django\\Blog\\user\\urls.py'> (None:None) ''>, <URLPattern 'auth/register' [name='register']>], [<URLResolver <module 'user.urls' from 'D:\\Python\\Django\\Blog\\user\\urls.py'> (None:None) ''>, <URLPattern 'auth/login' [name='login']>], [<URLResolver <module 'user.urls' from 'D:\\Python\\Django\\Blog\\user\\urls.py'> (None:None) ''>, <URLPattern 'auth/logout' [name='logout']>], [<URLResolver <module 'blog.urls' from 'D:\\Python\\Django\\Blog\\blog\\urls.py'> (blog:blog) ''>, <URLPattern '' [name='index']>], [<URLResolver <module 'blog.urls' from 'D:\\Python\\Django\\Blog\\blog\\urls.py'> (blog:blog) ''>, <URLPattern 'search/result' [name='search']>], [<URLResolver <module 'blog.urls' from 'D:\\Python\\Django\\Blog\\blog\\urls.py'> (blog:blog) ''>, <URLPattern '<slug:category_slug>' [name='category']>], [<URLResolver <module 'blog.urls' from 'D:\\Python\\Django\\Blog\\blog\\urls.py'> (blog:blog) ''>, <URLPattern 'tags/<slug:tag_slug>' [name='tag']>], [<URLResolver <module 'blog.urls' from 'D:\\Python\\Django\\Blog\\blog\\urls.py'> (blog:blog) ''>, <URLPattern '<slug:category_slug>/<slug:post_slug>' [name='post']>]], 'path': 'media/images/2022/03/26/zinaida-bonami-v-moskovskom-dome-knigi_0fbd0cde24_opgh.jpg'}

[2022-03-30 22:00:16,298 views ERROR] 
Traceback (most recent call last):
  File "D:\Python\Django\Blog\venv\lib\site-packages\django\core\handlers\exception.py", line 47, in inner
    response = get_response(request)
  File "D:\Python\Django\Blog\venv\lib\site-packages\django\core\handlers\base.py", line 167, in _get_response
    callback, callback_args, callback_kwargs = self.resolve_request(request)
  File "D:\Python\Django\Blog\venv\lib\site-packages\django\core\handlers\base.py", line 290, in resolve_request
    resolver_match = resolver.resolve(request.path_info)
  File "D:\Python\Django\Blog\venv\lib\site-packages\django\urls\resolvers.py", line 619, in resolve
    raise Resolver404({'tried': tried, 'path': new_path})
django.urls.exceptions.Resolver404: {'tried': [[<URLResolver <URLPattern list> (admin:admin) 'admin/'>], [<URLResolver <module 'user.urls' from 'D:\\Python\\Django\\Blog\\user\\urls.py'> (None:None) ''>, <URLPattern 'auth/register' [name='register']>], [<URLResolver <module 'user.urls' from 'D:\\Python\\Django\\Blog\\user\\urls.py'> (None:None) ''>, <URLPattern 'auth/login' [name='login']>], [<URLResolver <module 'user.urls' from 'D:\\Python\\Django\\Blog\\user\\urls.py'> (None:None) ''>, <URLPattern 'auth/logout' [name='logout']>], [<URLResolver <module 'blog.urls' from 'D:\\Python\\Django\\Blog\\blog\\urls.py'> (blog:blog) ''>, <URLPattern '' [name='index']>], [<URLResolver <module 'blog.urls' from 'D:\\Python\\Django\\Blog\\blog\\urls.py'> (blog:blog) ''>, <URLPattern 'search/result' [name='search']>], [<URLResolver <module 'blog.urls' from 'D:\\Python\\Django\\Blog\\blog\\urls.py'> (blog:blog) ''>, <URLPattern '<slug:category_slug>' [name='category']>], [<URLResolver <module 'blog.urls' from 'D:\\Python\\Django\\Blog\\blog\\urls.py'> (blog:blog) ''>, <URLPattern 'tags/<slug:tag_slug>' [name='tag']>], [<URLResolver <module 'blog.urls' from 'D:\\Python\\Django\\Blog\\blog\\urls.py'> (blog:blog) ''>, <URLPattern '<slug:category_slug>/<slug:post_slug>' [name='post']>]], 'path': 'media/images/2022/03/26/original-1e3a9b0322e85ba64376e6de6a9a0065.jpg'}

[2022-03-30 22:00:16,311 views ERROR] 
Traceback (most recent call last):
  File "D:\Python\Django\Blog\venv\lib\site-packages\django\core\handlers\exception.py", line 47, in inner
    response = get_response(request)
  File "D:\Python\Django\Blog\venv\lib\site-packages\django\core\handlers\base.py", line 167, in _get_response
    callback, callback_args, callback_kwargs = self.resolve_request(request)
  File "D:\Python\Django\Blog\venv\lib\site-packages\django\core\handlers\base.py", line 290, in resolve_request
    resolver_match = resolver.resolve(request.path_info)
  File "D:\Python\Django\Blog\venv\lib\site-packages\django\urls\resolvers.py", line 619, in resolve
    raise Resolver404({'tried': tried, 'path': new_path})
django.urls.exceptions.Resolver404: {'tried': [[<URLResolver <URLPattern list> (admin:admin) 'admin/'>], [<URLResolver <module 'user.urls' from 'D:\\Python\\Django\\Blog\\user\\urls.py'> (None:None) ''>, <URLPattern 'auth/register' [name='register']>], [<URLResolver <module 'user.urls' from 'D:\\Python\\Django\\Blog\\user\\urls.py'> (None:None) ''>, <URLPattern 'auth/login' [name='login']>], [<URLResolver <module 'user.urls' from 'D:\\Python\\Django\\Blog\\user\\urls.py'> (None:None) ''>, <URLPattern 'auth/logout' [name='logout']>], [<URLResolver <module 'blog.urls' from 'D:\\Python\\Django\\Blog\\blog\\urls.py'> (blog:blog) ''>, <URLPattern '' [name='index']>], [<URLResolver <module 'blog.urls' from 'D:\\Python\\Django\\Blog\\blog\\urls.py'> (blog:blog) ''>, <URLPattern 'search/result' [name='search']>], [<URLResolver <module 'blog.urls' from 'D:\\Python\\Django\\Blog\\blog\\urls.py'> (blog:blog) ''>, <URLPattern '<slug:category_slug>' [name='category']>], [<URLResolver <module 'blog.urls' from 'D:\\Python\\Django\\Blog\\blog\\urls.py'> (blog:blog) ''>, <URLPattern 'tags/<slug:tag_slug>' [name='tag']>], [<URLResolver <module 'blog.urls' from 'D:\\Python\\Django\\Blog\\blog\\urls.py'> (blog:blog) ''>, <URLPattern '<slug:category_slug>/<slug:post_slug>' [name='post']>]], 'path': 'static/blog/css/styles-listview.css'}

[2022-03-30 22:00:16,435 views ERROR] 
Traceback (most recent call last):
  File "D:\Python\Django\Blog\venv\lib\site-packages\django\core\handlers\exception.py", line 47, in inner
    response = get_response(request)
  File "D:\Python\Django\Blog\venv\lib\site-packages\django\core\handlers\base.py", line 167, in _get_response
    callback, callback_args, callback_kwargs = self.resolve_request(request)
  File "D:\Python\Django\Blog\venv\lib\site-packages\django\core\handlers\base.py", line 290, in resolve_request
    resolver_match = resolver.resolve(request.path_info)
  File "D:\Python\Django\Blog\venv\lib\site-packages\django\urls\resolvers.py", line 619, in resolve
    raise Resolver404({'tried': tried, 'path': new_path})
django.urls.exceptions.Resolver404: {'tried': [[<URLResolver <URLPattern list> (admin:admin) 'admin/'>], [<URLResolver <module 'user.urls' from 'D:\\Python\\Django\\Blog\\user\\urls.py'> (None:None) ''>, <URLPattern 'auth/register' [name='register']>], [<URLResolver <module 'user.urls' from 'D:\\Python\\Django\\Blog\\user\\urls.py'> (None:None) ''>, <URLPattern 'auth/login' [name='login']>], [<URLResolver <module 'user.urls' from 'D:\\Python\\Django\\Blog\\user\\urls.py'> (None:None) ''>, <URLPattern 'auth/logout' [name='logout']>], [<URLResolver <module 'blog.urls' from 'D:\\Python\\Django\\Blog\\blog\\urls.py'> (blog:blog) ''>, <URLPattern '' [name='index']>], [<URLResolver <module 'blog.urls' from 'D:\\Python\\Django\\Blog\\blog\\urls.py'> (blog:blog) ''>, <URLPattern 'search/result' [name='search']>], [<URLResolver <module 'blog.urls' from 'D:\\Python\\Django\\Blog\\blog\\urls.py'> (blog:blog) ''>, <URLPattern '<slug:category_slug>' [name='category']>], [<URLResolver <module 'blog.urls' from 'D:\\Python\\Django\\Blog\\blog\\urls.py'> (blog:blog) ''>, <URLPattern 'tags/<slug:tag_slug>' [name='tag']>], [<URLResolver <module 'blog.urls' from 'D:\\Python\\Django\\Blog\\blog\\urls.py'> (blog:blog) ''>, <URLPattern '<slug:category_slug>/<slug:post_slug>' [name='post']>]], 'path': 'media/images/2022/03/26/zinaida-bonami-v-moskovskom-dome-knigi_0fbd0cde24_opgh.jpg'}

[2022-03-30 22:00:16,802 views ERROR] 
Traceback (most recent call last):
  File "D:\Python\Django\Blog\venv\lib\site-packages\django\core\handlers\exception.py", line 47, in inner
    response = get_response(request)
  File "D:\Python\Django\Blog\venv\lib\site-packages\django\core\handlers\base.py", line 167, in _get_response
    callback, callback_args, callback_kwargs = self.resolve_request(request)
  File "D:\Python\Django\Blog\venv\lib\site-packages\django\core\handlers\base.py", line 290, in resolve_request
    resolver_match = resolver.resolve(request.path_info)
  File "D:\Python\Django\Blog\venv\lib\site-packages\django\urls\resolvers.py", line 619, in resolve
    raise Resolver404({'tried': tried, 'path': new_path})
django.urls.exceptions.Resolver404: {'tried': [[<URLResolver <URLPattern list> (admin:admin) 'admin/'>], [<URLResolver <module 'user.urls' from 'D:\\Python\\Django\\Blog\\user\\urls.py'> (None:None) ''>, <URLPattern 'auth/register' [name='register']>], [<URLResolver <module 'user.urls' from 'D:\\Python\\Django\\Blog\\user\\urls.py'> (None:None) ''>, <URLPattern 'auth/login' [name='login']>], [<URLResolver <module 'user.urls' from 'D:\\Python\\Django\\Blog\\user\\urls.py'> (None:None) ''>, <URLPattern 'auth/logout' [name='logout']>], [<URLResolver <module 'blog.urls' from 'D:\\Python\\Django\\Blog\\blog\\urls.py'> (blog:blog) ''>, <URLPattern '' [name='index']>], [<URLResolver <module 'blog.urls' from 'D:\\Python\\Django\\Blog\\blog\\urls.py'> (blog:blog) ''>, <URLPattern 'search/result' [name='search']>], [<URLResolver <module 'blog.urls' from 'D:\\Python\\Django\\Blog\\blog\\urls.py'> (blog:blog) ''>, <URLPattern '<slug:category_slug>' [name='category']>], [<URLResolver <module 'blog.urls' from 'D:\\Python\\Django\\Blog\\blog\\urls.py'> (blog:blog) ''>, <URLPattern 'tags/<slug:tag_slug>' [name='tag']>], [<URLResolver <module 'blog.urls' from 'D:\\Python\\Django\\Blog\\blog\\urls.py'> (blog:blog) ''>, <URLPattern '<slug:category_slug>/<slug:post_slug>' [name='post']>]], 'path': 'favicon.ico'}

[2022-03-30 22:02:28,571 views ERROR] 
Traceback (most recent call last):
  File "D:\Python\Django\Blog\venv\lib\site-packages\django\core\handlers\exception.py", line 47, in inner
    response = get_response(request)
  File "D:\Python\Django\Blog\venv\lib\site-packages\django\core\handlers\base.py", line 167, in _get_response
    callback, callback_args, callback_kwargs = self.resolve_request(request)
  File "D:\Python\Django\Blog\venv\lib\site-packages\django\core\handlers\base.py", line 290, in resolve_request
    resolver_match = resolver.resolve(request.path_info)
  File "D:\Python\Django\Blog\venv\lib\site-packages\django\urls\resolvers.py", line 619, in resolve
    raise Resolver404({'tried': tried, 'path': new_path})
django.urls.exceptions.Resolver404: {'tried': [[<URLResolver <URLPattern list> (admin:admin) 'admin/'>], [<URLResolver <module 'user.urls' from 'D:\\Python\\Django\\Blog\\user\\urls.py'> (None:None) ''>, <URLPattern 'auth/register' [name='register']>], [<URLResolver <module 'user.urls' from 'D:\\Python\\Django\\Blog\\user\\urls.py'> (None:None) ''>, <URLPattern 'auth/login' [name='login']>], [<URLResolver <module 'user.urls' from 'D:\\Python\\Django\\Blog\\user\\urls.py'> (None:None) ''>, <URLPattern 'auth/logout' [name='logout']>], [<URLResolver <module 'blog.urls' from 'D:\\Python\\Django\\Blog\\blog\\urls.py'> (blog:blog) ''>, <URLPattern '' [name='index']>], [<URLResolver <module 'blog.urls' from 'D:\\Python\\Django\\Blog\\blog\\urls.py'> (blog:blog) ''>, <URLPattern 'search/result' [name='search']>], [<URLResolver <module 'blog.urls' from 'D:\\Python\\Django\\Blog\\blog\\urls.py'> (blog:blog) ''>, <URLPattern '<slug:category_slug>' [name='category']>], [<URLResolver <module 'blog.urls' from 'D:\\Python\\Django\\Blog\\blog\\urls.py'> (blog:blog) ''>, <URLPattern 'tags/<slug:tag_slug>' [name='tag']>], [<URLResolver <module 'blog.urls' from 'D:\\Python\\Django\\Blog\\blog\\urls.py'> (blog:blog) ''>, <URLPattern '<slug:category_slug>/<slug:post_slug>' [name='post']>]], 'path': 'media/images/2022/03/26/original-1e3a9b0322e85ba64376e6de6a9a0065.jpg'}

[2022-03-30 22:02:28,572 views ERROR] 
Traceback (most recent call last):
  File "D:\Python\Django\Blog\venv\lib\site-packages\django\core\handlers\exception.py", line 47, in inner
    response = get_response(request)
  File "D:\Python\Django\Blog\venv\lib\site-packages\django\core\handlers\base.py", line 167, in _get_response
    callback, callback_args, callback_kwargs = self.resolve_request(request)
  File "D:\Python\Django\Blog\venv\lib\site-packages\django\core\handlers\base.py", line 290, in resolve_request
    resolver_match = resolver.resolve(request.path_info)
  File "D:\Python\Django\Blog\venv\lib\site-packages\django\urls\resolvers.py", line 619, in resolve
    raise Resolver404({'tried': tried, 'path': new_path})
django.urls.exceptions.Resolver404: {'tried': [[<URLResolver <URLPattern list> (admin:admin) 'admin/'>], [<URLResolver <module 'user.urls' from 'D:\\Python\\Django\\Blog\\user\\urls.py'> (None:None) ''>, <URLPattern 'auth/register' [name='register']>], [<URLResolver <module 'user.urls' from 'D:\\Python\\Django\\Blog\\user\\urls.py'> (None:None) ''>, <URLPattern 'auth/login' [name='login']>], [<URLResolver <module 'user.urls' from 'D:\\Python\\Django\\Blog\\user\\urls.py'> (None:None) ''>, <URLPattern 'auth/logout' [name='logout']>], [<URLResolver <module 'blog.urls' from 'D:\\Python\\Django\\Blog\\blog\\urls.py'> (blog:blog) ''>, <URLPattern '' [name='index']>], [<URLResolver <module 'blog.urls' from 'D:\\Python\\Django\\Blog\\blog\\urls.py'> (blog:blog) ''>, <URLPattern 'search/result' [name='search']>], [<URLResolver <module 'blog.urls' from 'D:\\Python\\Django\\Blog\\blog\\urls.py'> (blog:blog) ''>, <URLPattern '<slug:category_slug>' [name='category']>], [<URLResolver <module 'blog.urls' from 'D:\\Python\\Django\\Blog\\blog\\urls.py'> (blog:blog) ''>, <URLPattern 'tags/<slug:tag_slug>' [name='tag']>], [<URLResolver <module 'blog.urls' from 'D:\\Python\\Django\\Blog\\blog\\urls.py'> (blog:blog) ''>, <URLPattern '<slug:category_slug>/<slug:post_slug>' [name='post']>]], 'path': 'static/blog/css/styles-listview.css'}

[2022-03-30 22:02:28,735 views ERROR] 
Traceback (most recent call last):
  File "D:\Python\Django\Blog\venv\lib\site-packages\django\core\handlers\exception.py", line 47, in inner
    response = get_response(request)
  File "D:\Python\Django\Blog\venv\lib\site-packages\django\core\handlers\base.py", line 167, in _get_response
    callback, callback_args, callback_kwargs = self.resolve_request(request)
  File "D:\Python\Django\Blog\venv\lib\site-packages\django\core\handlers\base.py", line 290, in resolve_request
    resolver_match = resolver.resolve(request.path_info)
  File "D:\Python\Django\Blog\venv\lib\site-packages\django\urls\resolvers.py", line 619, in resolve
    raise Resolver404({'tried': tried, 'path': new_path})
django.urls.exceptions.Resolver404: {'tried': [[<URLResolver <URLPattern list> (admin:admin) 'admin/'>], [<URLResolver <module 'user.urls' from 'D:\\Python\\Django\\Blog\\user\\urls.py'> (None:None) ''>, <URLPattern 'auth/register' [name='register']>], [<URLResolver <module 'user.urls' from 'D:\\Python\\Django\\Blog\\user\\urls.py'> (None:None) ''>, <URLPattern 'auth/login' [name='login']>], [<URLResolver <module 'user.urls' from 'D:\\Python\\Django\\Blog\\user\\urls.py'> (None:None) ''>, <URLPattern 'auth/logout' [name='logout']>], [<URLResolver <module 'blog.urls' from 'D:\\Python\\Django\\Blog\\blog\\urls.py'> (blog:blog) ''>, <URLPattern '' [name='index']>], [<URLResolver <module 'blog.urls' from 'D:\\Python\\Django\\Blog\\blog\\urls.py'> (blog:blog) ''>, <URLPattern 'search/result' [name='search']>], [<URLResolver <module 'blog.urls' from 'D:\\Python\\Django\\Blog\\blog\\urls.py'> (blog:blog) ''>, <URLPattern '<slug:category_slug>' [name='category']>], [<URLResolver <module 'blog.urls' from 'D:\\Python\\Django\\Blog\\blog\\urls.py'> (blog:blog) ''>, <URLPattern 'tags/<slug:tag_slug>' [name='tag']>], [<URLResolver <module 'blog.urls' from 'D:\\Python\\Django\\Blog\\blog\\urls.py'> (blog:blog) ''>, <URLPattern '<slug:category_slug>/<slug:post_slug>' [name='post']>]], 'path': 'media/images/2022/03/26/zinaida-bonami-v-moskovskom-dome-knigi_0fbd0cde24_opgh.jpg'}

[2022-03-30 22:02:44,307 views ERROR] 
Traceback (most recent call last):
  File "D:\Python\Django\Blog\venv\lib\site-packages\django\core\handlers\exception.py", line 47, in inner
    response = get_response(request)
  File "D:\Python\Django\Blog\venv\lib\site-packages\django\core\handlers\base.py", line 167, in _get_response
    callback, callback_args, callback_kwargs = self.resolve_request(request)
  File "D:\Python\Django\Blog\venv\lib\site-packages\django\core\handlers\base.py", line 290, in resolve_request
    resolver_match = resolver.resolve(request.path_info)
  File "D:\Python\Django\Blog\venv\lib\site-packages\django\urls\resolvers.py", line 619, in resolve
    raise Resolver404({'tried': tried, 'path': new_path})
django.urls.exceptions.Resolver404: {'tried': [[<URLResolver <URLPattern list> (admin:admin) 'admin/'>], [<URLResolver <module 'user.urls' from 'D:\\Python\\Django\\Blog\\user\\urls.py'> (None:None) ''>, <URLPattern 'auth/register' [name='register']>], [<URLResolver <module 'user.urls' from 'D:\\Python\\Django\\Blog\\user\\urls.py'> (None:None) ''>, <URLPattern 'auth/login' [name='login']>], [<URLResolver <module 'user.urls' from 'D:\\Python\\Django\\Blog\\user\\urls.py'> (None:None) ''>, <URLPattern 'auth/logout' [name='logout']>], [<URLResolver <module 'blog.urls' from 'D:\\Python\\Django\\Blog\\blog\\urls.py'> (blog:blog) ''>, <URLPattern '' [name='index']>], [<URLResolver <module 'blog.urls' from 'D:\\Python\\Django\\Blog\\blog\\urls.py'> (blog:blog) ''>, <URLPattern 'search/result' [name='search']>], [<URLResolver <module 'blog.urls' from 'D:\\Python\\Django\\Blog\\blog\\urls.py'> (blog:blog) ''>, <URLPattern '<slug:category_slug>' [name='category']>], [<URLResolver <module 'blog.urls' from 'D:\\Python\\Django\\Blog\\blog\\urls.py'> (blog:blog) ''>, <URLPattern 'tags/<slug:tag_slug>' [name='tag']>], [<URLResolver <module 'blog.urls' from 'D:\\Python\\Django\\Blog\\blog\\urls.py'> (blog:blog) ''>, <URLPattern '<slug:category_slug>/<slug:post_slug>' [name='post']>]], 'path': 'static/blog/css/styles-listview.css'}

[2022-03-30 22:02:44,311 views ERROR] 
Traceback (most recent call last):
  File "D:\Python\Django\Blog\venv\lib\site-packages\django\core\handlers\exception.py", line 47, in inner
    response = get_response(request)
  File "D:\Python\Django\Blog\venv\lib\site-packages\django\core\handlers\base.py", line 167, in _get_response
    callback, callback_args, callback_kwargs = self.resolve_request(request)
  File "D:\Python\Django\Blog\venv\lib\site-packages\django\core\handlers\base.py", line 290, in resolve_request
    resolver_match = resolver.resolve(request.path_info)
  File "D:\Python\Django\Blog\venv\lib\site-packages\django\urls\resolvers.py", line 619, in resolve
    raise Resolver404({'tried': tried, 'path': new_path})
django.urls.exceptions.Resolver404: {'tried': [[<URLResolver <URLPattern list> (admin:admin) 'admin/'>], [<URLResolver <module 'user.urls' from 'D:\\Python\\Django\\Blog\\user\\urls.py'> (None:None) ''>, <URLPattern 'auth/register' [name='register']>], [<URLResolver <module 'user.urls' from 'D:\\Python\\Django\\Blog\\user\\urls.py'> (None:None) ''>, <URLPattern 'auth/login' [name='login']>], [<URLResolver <module 'user.urls' from 'D:\\Python\\Django\\Blog\\user\\urls.py'> (None:None) ''>, <URLPattern 'auth/logout' [name='logout']>], [<URLResolver <module 'blog.urls' from 'D:\\Python\\Django\\Blog\\blog\\urls.py'> (blog:blog) ''>, <URLPattern '' [name='index']>], [<URLResolver <module 'blog.urls' from 'D:\\Python\\Django\\Blog\\blog\\urls.py'> (blog:blog) ''>, <URLPattern 'search/result' [name='search']>], [<URLResolver <module 'blog.urls' from 'D:\\Python\\Django\\Blog\\blog\\urls.py'> (blog:blog) ''>, <URLPattern '<slug:category_slug>' [name='category']>], [<URLResolver <module 'blog.urls' from 'D:\\Python\\Django\\Blog\\blog\\urls.py'> (blog:blog) ''>, <URLPattern 'tags/<slug:tag_slug>' [name='tag']>], [<URLResolver <module 'blog.urls' from 'D:\\Python\\Django\\Blog\\blog\\urls.py'> (blog:blog) ''>, <URLPattern '<slug:category_slug>/<slug:post_slug>' [name='post']>]], 'path': 'media/images/2022/03/26/original-1e3a9b0322e85ba64376e6de6a9a0065.jpg'}

[2022-03-30 22:02:44,324 views ERROR] 
Traceback (most recent call last):
  File "D:\Python\Django\Blog\venv\lib\site-packages\django\core\handlers\exception.py", line 47, in inner
    response = get_response(request)
  File "D:\Python\Django\Blog\venv\lib\site-packages\django\core\handlers\base.py", line 167, in _get_response
    callback, callback_args, callback_kwargs = self.resolve_request(request)
  File "D:\Python\Django\Blog\venv\lib\site-packages\django\core\handlers\base.py", line 290, in resolve_request
    resolver_match = resolver.resolve(request.path_info)
  File "D:\Python\Django\Blog\venv\lib\site-packages\django\urls\resolvers.py", line 619, in resolve
    raise Resolver404({'tried': tried, 'path': new_path})
django.urls.exceptions.Resolver404: {'tried': [[<URLResolver <URLPattern list> (admin:admin) 'admin/'>], [<URLResolver <module 'user.urls' from 'D:\\Python\\Django\\Blog\\user\\urls.py'> (None:None) ''>, <URLPattern 'auth/register' [name='register']>], [<URLResolver <module 'user.urls' from 'D:\\Python\\Django\\Blog\\user\\urls.py'> (None:None) ''>, <URLPattern 'auth/login' [name='login']>], [<URLResolver <module 'user.urls' from 'D:\\Python\\Django\\Blog\\user\\urls.py'> (None:None) ''>, <URLPattern 'auth/logout' [name='logout']>], [<URLResolver <module 'blog.urls' from 'D:\\Python\\Django\\Blog\\blog\\urls.py'> (blog:blog) ''>, <URLPattern '' [name='index']>], [<URLResolver <module 'blog.urls' from 'D:\\Python\\Django\\Blog\\blog\\urls.py'> (blog:blog) ''>, <URLPattern 'search/result' [name='search']>], [<URLResolver <module 'blog.urls' from 'D:\\Python\\Django\\Blog\\blog\\urls.py'> (blog:blog) ''>, <URLPattern '<slug:category_slug>' [name='category']>], [<URLResolver <module 'blog.urls' from 'D:\\Python\\Django\\Blog\\blog\\urls.py'> (blog:blog) ''>, <URLPattern 'tags/<slug:tag_slug>' [name='tag']>], [<URLResolver <module 'blog.urls' from 'D:\\Python\\Django\\Blog\\blog\\urls.py'> (blog:blog) ''>, <URLPattern '<slug:category_slug>/<slug:post_slug>' [name='post']>]], 'path': 'media/images/2022/03/26/zinaida-bonami-v-moskovskom-dome-knigi_0fbd0cde24_opgh.jpg'}

[2022-03-30 22:02:51,244 views ERROR] 
Traceback (most recent call last):
  File "D:\Python\Django\Blog\venv\lib\site-packages\django\core\handlers\exception.py", line 47, in inner
    response = get_response(request)
  File "D:\Python\Django\Blog\venv\lib\site-packages\django\core\handlers\base.py", line 167, in _get_response
    callback, callback_args, callback_kwargs = self.resolve_request(request)
  File "D:\Python\Django\Blog\venv\lib\site-packages\django\core\handlers\base.py", line 290, in resolve_request
    resolver_match = resolver.resolve(request.path_info)
  File "D:\Python\Django\Blog\venv\lib\site-packages\django\urls\resolvers.py", line 619, in resolve
    raise Resolver404({'tried': tried, 'path': new_path})
django.urls.exceptions.Resolver404: {'tried': [[<URLResolver <URLPattern list> (admin:admin) 'admin/'>], [<URLResolver <module 'user.urls' from 'D:\\Python\\Django\\Blog\\user\\urls.py'> (None:None) ''>, <URLPattern 'auth/register' [name='register']>], [<URLResolver <module 'user.urls' from 'D:\\Python\\Django\\Blog\\user\\urls.py'> (None:None) ''>, <URLPattern 'auth/login' [name='login']>], [<URLResolver <module 'user.urls' from 'D:\\Python\\Django\\Blog\\user\\urls.py'> (None:None) ''>, <URLPattern 'auth/logout' [name='logout']>], [<URLResolver <module 'blog.urls' from 'D:\\Python\\Django\\Blog\\blog\\urls.py'> (blog:blog) ''>, <URLPattern '' [name='index']>], [<URLResolver <module 'blog.urls' from 'D:\\Python\\Django\\Blog\\blog\\urls.py'> (blog:blog) ''>, <URLPattern 'search/result' [name='search']>], [<URLResolver <module 'blog.urls' from 'D:\\Python\\Django\\Blog\\blog\\urls.py'> (blog:blog) ''>, <URLPattern '<slug:category_slug>' [name='category']>], [<URLResolver <module 'blog.urls' from 'D:\\Python\\Django\\Blog\\blog\\urls.py'> (blog:blog) ''>, <URLPattern 'tags/<slug:tag_slug>' [name='tag']>], [<URLResolver <module 'blog.urls' from 'D:\\Python\\Django\\Blog\\blog\\urls.py'> (blog:blog) ''>, <URLPattern '<slug:category_slug>/<slug:post_slug>' [name='post']>]], 'path': 'static/blog/css/styles-listview.css'}

